[2022-12-01T17:25:43.274+0000] {taskinstance.py:1165} INFO - Dependencies all met for <TaskInstance: Practice_Airflow.Practice_b manual__2022-12-01T17:25:38.315568+00:00 [queued]>
[2022-12-01T17:25:43.281+0000] {taskinstance.py:1165} INFO - Dependencies all met for <TaskInstance: Practice_Airflow.Practice_b manual__2022-12-01T17:25:38.315568+00:00 [queued]>
[2022-12-01T17:25:43.282+0000] {taskinstance.py:1362} INFO - 
--------------------------------------------------------------------------------
[2022-12-01T17:25:43.282+0000] {taskinstance.py:1363} INFO - Starting attempt 1 of 1
[2022-12-01T17:25:43.282+0000] {taskinstance.py:1364} INFO - 
--------------------------------------------------------------------------------
[2022-12-01T17:25:43.332+0000] {taskinstance.py:1383} INFO - Executing <Task(PythonOperator): Practice_b> on 2022-12-01 17:25:38.315568+00:00
[2022-12-01T17:25:43.335+0000] {standard_task_runner.py:55} INFO - Started process 4803 to run task
[2022-12-01T17:25:43.337+0000] {standard_task_runner.py:82} INFO - Running: ['***', 'tasks', 'run', 'Practice_Airflow', 'Practice_b', 'manual__2022-12-01T17:25:38.315568+00:00', '--job-id', '54', '--raw', '--subdir', 'DAGS_FOLDER/Airflow_pr.py', '--cfg-path', '/tmp/tmpz7t5j8cd']
[2022-12-01T17:25:43.338+0000] {standard_task_runner.py:83} INFO - Job 54: Subtask Practice_b
[2022-12-01T17:25:43.398+0000] {task_command.py:376} INFO - Running <TaskInstance: Practice_Airflow.Practice_b manual__2022-12-01T17:25:38.315568+00:00 [running]> on host a5be4f489b88
[2022-12-01T17:25:43.506+0000] {taskinstance.py:1592} INFO - Exporting the following env vars:
AIRFLOW_CTX_DAG_OWNER=***
AIRFLOW_CTX_DAG_ID=Practice_Airflow
AIRFLOW_CTX_TASK_ID=Practice_b
AIRFLOW_CTX_EXECUTION_DATE=2022-12-01T17:25:38.315568+00:00
AIRFLOW_CTX_TRY_NUMBER=1
AIRFLOW_CTX_DAG_RUN_ID=manual__2022-12-01T17:25:38.315568+00:00
[2022-12-01T17:25:43.507+0000] {taskinstance.py:1851} ERROR - Task failed with exception
Traceback (most recent call last):
  File "/home/airflow/.local/lib/python3.7/site-packages/airflow/operators/python.py", line 175, in execute
    return_value = self.execute_callable()
  File "/home/airflow/.local/lib/python3.7/site-packages/airflow/operators/python.py", line 193, in execute_callable
    return self.python_callable(*self.op_args, **self.op_kwargs)
  File "/opt/airflow/dags/Airflow_pr.py", line 26, in b
    csv_rows = task_instance.xcom_pull(task_ids='Practice_a')
NameError: name 'task_instance' is not defined
[2022-12-01T17:25:43.514+0000] {taskinstance.py:1406} INFO - Marking task as FAILED. dag_id=Practice_Airflow, task_id=Practice_b, execution_date=20221201T172538, start_date=20221201T172543, end_date=20221201T172543
[2022-12-01T17:25:43.557+0000] {standard_task_runner.py:105} ERROR - Failed to execute job 54 for task Practice_b (name 'task_instance' is not defined; 4803)
[2022-12-01T17:25:43.589+0000] {local_task_job.py:159} INFO - Task exited with return code 1
[2022-12-01T17:25:43.601+0000] {taskinstance.py:2623} INFO - 0 downstream tasks scheduled from follow-on schedule check
