[2022-12-05T11:03:56.578+0000] {taskinstance.py:1165} INFO - Dependencies all met for <TaskInstance: Practice_Airflow.task_d_e scheduled__2022-12-05T09:02:00+00:00 [queued]>
[2022-12-05T11:03:56.586+0000] {taskinstance.py:1165} INFO - Dependencies all met for <TaskInstance: Practice_Airflow.task_d_e scheduled__2022-12-05T09:02:00+00:00 [queued]>
[2022-12-05T11:03:56.586+0000] {taskinstance.py:1362} INFO - 
--------------------------------------------------------------------------------
[2022-12-05T11:03:56.586+0000] {taskinstance.py:1363} INFO - Starting attempt 1 of 1
[2022-12-05T11:03:56.587+0000] {taskinstance.py:1364} INFO - 
--------------------------------------------------------------------------------
[2022-12-05T11:03:56.662+0000] {taskinstance.py:1383} INFO - Executing <Task(PythonOperator): task_d_e> on 2022-12-05 09:02:00+00:00
[2022-12-05T11:03:56.666+0000] {standard_task_runner.py:55} INFO - Started process 1010 to run task
[2022-12-05T11:03:56.668+0000] {standard_task_runner.py:82} INFO - Running: ['***', 'tasks', 'run', 'Practice_Airflow', 'task_d_e', 'scheduled__2022-12-05T09:02:00+00:00', '--job-id', '380', '--raw', '--subdir', 'DAGS_FOLDER/Airflow_pr.py', '--cfg-path', '/tmp/tmpt3h9s78k']
[2022-12-05T11:03:56.671+0000] {standard_task_runner.py:83} INFO - Job 380: Subtask task_d_e
[2022-12-05T11:03:56.790+0000] {task_command.py:376} INFO - Running <TaskInstance: Practice_Airflow.task_d_e scheduled__2022-12-05T09:02:00+00:00 [running]> on host a5be4f489b88
[2022-12-05T11:03:56.931+0000] {taskinstance.py:1592} INFO - Exporting the following env vars:
AIRFLOW_CTX_DAG_OWNER=***
AIRFLOW_CTX_DAG_ID=Practice_Airflow
AIRFLOW_CTX_TASK_ID=task_d_e
AIRFLOW_CTX_EXECUTION_DATE=2022-12-05T09:02:00+00:00
AIRFLOW_CTX_TRY_NUMBER=1
AIRFLOW_CTX_DAG_RUN_ID=scheduled__2022-12-05T09:02:00+00:00
[2022-12-05T11:03:56.941+0000] {taskinstance.py:1851} ERROR - Task failed with exception
Traceback (most recent call last):
  File "/home/airflow/.local/lib/python3.7/site-packages/airflow/operators/python.py", line 175, in execute
    return_value = self.execute_callable()
  File "/home/airflow/.local/lib/python3.7/site-packages/airflow/operators/python.py", line 193, in execute_callable
    return self.python_callable(*self.op_args, **self.op_kwargs)
  File "/opt/airflow/dags/Airflow_pr.py", line 87, in task_d_e
    col2 = list(map(int, list(my_list[1])))
IndexError: list index out of range
[2022-12-05T11:03:56.952+0000] {taskinstance.py:1406} INFO - Marking task as FAILED. dag_id=Practice_Airflow, task_id=task_d_e, execution_date=20221205T090200, start_date=20221205T110356, end_date=20221205T110356
[2022-12-05T11:03:57.003+0000] {standard_task_runner.py:105} ERROR - Failed to execute job 380 for task task_d_e (list index out of range; 1010)
[2022-12-05T11:03:57.041+0000] {local_task_job.py:159} INFO - Task exited with return code 1
[2022-12-05T11:03:57.056+0000] {taskinstance.py:2623} INFO - 0 downstream tasks scheduled from follow-on schedule check
