[2022-12-01T17:33:43.766+0000] {taskinstance.py:1165} INFO - Dependencies all met for <TaskInstance: Practice_Airflow.Practice_b manual__2022-12-01T17:33:38.821131+00:00 [queued]>
[2022-12-01T17:33:43.773+0000] {taskinstance.py:1165} INFO - Dependencies all met for <TaskInstance: Practice_Airflow.Practice_b manual__2022-12-01T17:33:38.821131+00:00 [queued]>
[2022-12-01T17:33:43.774+0000] {taskinstance.py:1362} INFO - 
--------------------------------------------------------------------------------
[2022-12-01T17:33:43.774+0000] {taskinstance.py:1363} INFO - Starting attempt 1 of 1
[2022-12-01T17:33:43.774+0000] {taskinstance.py:1364} INFO - 
--------------------------------------------------------------------------------
[2022-12-01T17:33:43.845+0000] {taskinstance.py:1383} INFO - Executing <Task(PythonOperator): Practice_b> on 2022-12-01 17:33:38.821131+00:00
[2022-12-01T17:33:43.850+0000] {standard_task_runner.py:55} INFO - Started process 5204 to run task
[2022-12-01T17:33:43.851+0000] {standard_task_runner.py:82} INFO - Running: ['***', 'tasks', 'run', 'Practice_Airflow', 'Practice_b', 'manual__2022-12-01T17:33:38.821131+00:00', '--job-id', '60', '--raw', '--subdir', 'DAGS_FOLDER/Airflow_pr.py', '--cfg-path', '/tmp/tmpo3x_qt6n']
[2022-12-01T17:33:43.852+0000] {standard_task_runner.py:83} INFO - Job 60: Subtask Practice_b
[2022-12-01T17:33:43.927+0000] {task_command.py:376} INFO - Running <TaskInstance: Practice_Airflow.Practice_b manual__2022-12-01T17:33:38.821131+00:00 [running]> on host a5be4f489b88
[2022-12-01T17:33:44.039+0000] {taskinstance.py:1592} INFO - Exporting the following env vars:
AIRFLOW_CTX_DAG_OWNER=***
AIRFLOW_CTX_DAG_ID=Practice_Airflow
AIRFLOW_CTX_TASK_ID=Practice_b
AIRFLOW_CTX_EXECUTION_DATE=2022-12-01T17:33:38.821131+00:00
AIRFLOW_CTX_TRY_NUMBER=1
AIRFLOW_CTX_DAG_RUN_ID=manual__2022-12-01T17:33:38.821131+00:00
[2022-12-01T17:33:44.057+0000] {taskinstance.py:1851} ERROR - Task failed with exception
Traceback (most recent call last):
  File "/home/airflow/.local/lib/python3.7/site-packages/airflow/operators/python.py", line 175, in execute
    return_value = self.execute_callable()
  File "/home/airflow/.local/lib/python3.7/site-packages/airflow/operators/python.py", line 193, in execute_callable
    return self.python_callable(*self.op_args, **self.op_kwargs)
  File "/opt/airflow/dags/Airflow_pr.py", line 29, in b
    df['new_column'] = [i for i in range(csv_rows - 1, 0 - 1)]
  File "/home/airflow/.local/lib/python3.7/site-packages/pandas/core/frame.py", line 3612, in __setitem__
    self._set_item(key, value)
  File "/home/airflow/.local/lib/python3.7/site-packages/pandas/core/frame.py", line 3784, in _set_item
    value = self._sanitize_column(value)
  File "/home/airflow/.local/lib/python3.7/site-packages/pandas/core/frame.py", line 4509, in _sanitize_column
    com.require_length_match(value, self.index)
  File "/home/airflow/.local/lib/python3.7/site-packages/pandas/core/common.py", line 532, in require_length_match
    "Length of values "
ValueError: Length of values (0) does not match length of index (200)
[2022-12-01T17:33:44.066+0000] {taskinstance.py:1406} INFO - Marking task as FAILED. dag_id=Practice_Airflow, task_id=Practice_b, execution_date=20221201T173338, start_date=20221201T173343, end_date=20221201T173344
[2022-12-01T17:33:44.104+0000] {standard_task_runner.py:105} ERROR - Failed to execute job 60 for task Practice_b (Length of values (0) does not match length of index (200); 5204)
[2022-12-01T17:33:44.144+0000] {local_task_job.py:159} INFO - Task exited with return code 1
[2022-12-01T17:33:44.157+0000] {taskinstance.py:2623} INFO - 0 downstream tasks scheduled from follow-on schedule check
