[2022-12-01T17:44:50.240+0000] {taskinstance.py:1165} INFO - Dependencies all met for <TaskInstance: Practice_Airflow.Practice_b manual__2022-12-01T17:44:44.776431+00:00 [queued]>
[2022-12-01T17:44:50.247+0000] {taskinstance.py:1165} INFO - Dependencies all met for <TaskInstance: Practice_Airflow.Practice_b manual__2022-12-01T17:44:44.776431+00:00 [queued]>
[2022-12-01T17:44:50.248+0000] {taskinstance.py:1362} INFO - 
--------------------------------------------------------------------------------
[2022-12-01T17:44:50.248+0000] {taskinstance.py:1363} INFO - Starting attempt 1 of 1
[2022-12-01T17:44:50.248+0000] {taskinstance.py:1364} INFO - 
--------------------------------------------------------------------------------
[2022-12-01T17:44:50.326+0000] {taskinstance.py:1383} INFO - Executing <Task(PythonOperator): Practice_b> on 2022-12-01 17:44:44.776431+00:00
[2022-12-01T17:44:50.330+0000] {standard_task_runner.py:55} INFO - Started process 5744 to run task
[2022-12-01T17:44:50.332+0000] {standard_task_runner.py:82} INFO - Running: ['***', 'tasks', 'run', 'Practice_Airflow', 'Practice_b', 'manual__2022-12-01T17:44:44.776431+00:00', '--job-id', '63', '--raw', '--subdir', 'DAGS_FOLDER/Airflow_pr.py', '--cfg-path', '/tmp/tmpcyyoj3h_']
[2022-12-01T17:44:50.333+0000] {standard_task_runner.py:83} INFO - Job 63: Subtask Practice_b
[2022-12-01T17:44:50.401+0000] {task_command.py:376} INFO - Running <TaskInstance: Practice_Airflow.Practice_b manual__2022-12-01T17:44:44.776431+00:00 [running]> on host a5be4f489b88
[2022-12-01T17:44:50.526+0000] {taskinstance.py:1592} INFO - Exporting the following env vars:
AIRFLOW_CTX_DAG_OWNER=***
AIRFLOW_CTX_DAG_ID=Practice_Airflow
AIRFLOW_CTX_TASK_ID=Practice_b
AIRFLOW_CTX_EXECUTION_DATE=2022-12-01T17:44:44.776431+00:00
AIRFLOW_CTX_TRY_NUMBER=1
AIRFLOW_CTX_DAG_RUN_ID=manual__2022-12-01T17:44:44.776431+00:00
[2022-12-01T17:44:50.545+0000] {taskinstance.py:1851} ERROR - Task failed with exception
Traceback (most recent call last):
  File "/home/airflow/.local/lib/python3.7/site-packages/airflow/operators/python.py", line 175, in execute
    return_value = self.execute_callable()
  File "/home/airflow/.local/lib/python3.7/site-packages/airflow/operators/python.py", line 193, in execute_callable
    return self.python_callable(*self.op_args, **self.op_kwargs)
  File "/opt/airflow/dags/Airflow_pr.py", line 29, in b
    df['new_column'] = pd.Series([i for i in range(csv_rows - 1, -1, -1)], ignore_index=True)
TypeError: __init__() got an unexpected keyword argument 'ignore_index'
[2022-12-01T17:44:50.554+0000] {taskinstance.py:1406} INFO - Marking task as FAILED. dag_id=Practice_Airflow, task_id=Practice_b, execution_date=20221201T174444, start_date=20221201T174450, end_date=20221201T174450
[2022-12-01T17:44:50.593+0000] {standard_task_runner.py:105} ERROR - Failed to execute job 63 for task Practice_b (__init__() got an unexpected keyword argument 'ignore_index'; 5744)
[2022-12-01T17:44:50.624+0000] {local_task_job.py:159} INFO - Task exited with return code 1
[2022-12-01T17:44:50.638+0000] {taskinstance.py:2623} INFO - 0 downstream tasks scheduled from follow-on schedule check
